<robot name="robo">
  <link name="root" />
  <link name="shoulder1" />
  <link name="shoulder2" />
  <link name="shoulder3" />
  <link name="elbow1" />
  <link name="wrist1" />
  <link name="wrist2" />
  <joint name="shoulder_yaw" type="revolute">
    <origin xyz="0.0 0.1 0.2" />
    <parent link="root" />
    <child link="shoulder1" />
    <axis xyz="0 0 1" />
    <limit lower="-1" upper="1.0" effort="0" velocity="1.0"/>
  </joint>
  <joint name="shoulder_pitch" type="revolute">
    <origin xyz="0.0 0.1 0.0" />
    <parent link="shoulder1" />
    <child link="shoulder2" />
    <axis xyz="0 1 0" />
    <limit lower="-1" upper="1.0" effort="0" velocity="1.0"/>
  </joint>
  <joint name="shoulder_roll" type="revolute">
    <origin xyz="0.0 0.1 0.0" />
    <parent link="shoulder2" />
    <child link="shoulder3" />
    <axis xyz="1 0 0" />
    <limit lower="-2" upper="1.0" effort="0" velocity="1.0"/>
  </joint>
  <joint name="elbow_pitch" type="revolute">
    <origin xyz="0.0 0.0 -0.2" />
    <parent link="shoulder3" />
    <child link="elbow1" />
    <axis xyz="0 1 0" />
    <limit lower="-2" upper="1.0" effort="0" velocity="1.0"/>
  </joint>
  <joint name="wrist_yaw" type="revolute">
    <origin xyz="0.0 0.0 -0.2" />
    <parent link="elbow1" />
    <child link="wrist1" />
    <axis xyz="0 0 1" />
    <limit lower="-2" upper="1.0" effort="0" velocity="1.0"/>
  </joint>
  <joint name="wrist_pitch" type="revolute">
    <origin xyz="0.0 0.0 -0.2" />
    <parent link="wrist1" />
    <child link="wrist2" />
    <axis xyz="0 1 0" />
    <limit lower="-2" upper="1.0" effort="0" velocity="1.0"/>
  </joint>
</robot>
